2024-05-21 14:38:36,648 - DEBUG - Logger set for ConfigManager
2024-05-21 14:38:36,649 - INFO - Application started
2024-05-21 14:38:36,953 - DEBUG - NetworkOperations initialized with ThreadPoolExecutor.
2024-05-21 14:38:36,962 - INFO - Pinging device with IP: 8.8.8.8
2024-05-21 14:38:36,962 - INFO - Pinging device with IP: 2.2.2.2
2024-05-21 14:38:36,963 - INFO - Pinging device with IP: 2.2.2.3
2024-05-21 14:38:39,186 - ERROR - Log file not found, creating a new one.
2024-05-21 14:38:39,186 - ERROR - Log file not found, creating a new one.
2024-05-21 14:38:39,186 - INFO - Log display auto-refreshed.
2024-05-21 14:38:41,106 - INFO - Result for device with IP 8.8.8.8: Online, Avg ping: 25.20 ms
2024-05-21 14:38:47,017 - INFO - Result for device with IP 2.2.2.3: Offline, Ping Timeout
2024-05-21 14:38:47,037 - INFO - Result for device with IP 2.2.2.2: Offline, Ping Timeout
2024-05-21 14:39:36,976 - INFO - Pinging device with IP: 8.8.8.8
2024-05-21 14:39:36,976 - INFO - Pinging device with IP: 2.2.2.2
2024-05-21 14:39:36,976 - INFO - Pinging device with IP: 2.2.2.3
2024-05-21 14:39:41,081 - INFO - Result for device with IP 8.8.8.8: Online, Avg ping: 24.00 ms
2024-05-21 14:39:47,004 - INFO - Result for device with IP 2.2.2.2: Offline, Ping Timeout
2024-05-21 14:39:47,014 - INFO - Result for device with IP 2.2.2.3: Offline, Ping Timeout
2024-05-21 14:40:25,612 - INFO - Application ended
2024-05-21 14:41:15,007 - DEBUG - Logger set for ConfigManager
2024-05-21 14:41:15,009 - INFO - Application started
2024-05-21 14:41:15,278 - DEBUG - NetworkOperations initialized with ThreadPoolExecutor.
2024-05-21 14:41:15,285 - INFO - Pinging device with IP: 8.8.8.8
2024-05-21 14:41:15,285 - INFO - Pinging device with IP: 2.2.2.2
2024-05-21 14:41:15,285 - INFO - Pinging device with IP: 2.2.2.3
2024-05-21 14:41:18,077 - INFO - Log display auto-refreshed.
2024-05-21 14:41:19,445 - INFO - Result for device with IP 8.8.8.8: Online, Avg ping: 24.60 ms
2024-05-21 14:41:21,523 - INFO - Application ended
2024-05-21 14:41:26,395 - ERROR - Failed to update device status: main thread is not in main loop
2024-05-21 14:41:26,395 - ERROR - Failed to update device status: main thread is not in main loop
2024-05-21 14:41:26,396 - ERROR - Error processing ping result for device 2.2.2.2: main thread is not in main loop
2024-05-21 14:41:26,397 - ERROR - Error processing ping result for device 2.2.2.3: main thread is not in main loop
2024-05-21 14:41:27,447 - ERROR - Failed to update device status: main thread is not in main loop
2024-05-21 14:41:27,447 - ERROR - Failed to update device status: main thread is not in main loop
2024-05-21 14:41:27,447 - ERROR - exception calling callback for <Future at 0x16f8ae98b90 state=finished returned str>
Traceback (most recent call last):
  File "c:\Users\ccollins\OneDrive - Tombstone Unified School District #1\Python NetMon\NetMon1.1.3.1\modules\network_operations.py", line 59, in process_ping_result
    self.update_callback(ip, status)
  File "c:\Users\ccollins\OneDrive - Tombstone Unified School District #1\Python NetMon\NetMon1.1.3.1\modules\application.py", line 62, in update_callback
    raise e
  File "c:\Users\ccollins\OneDrive - Tombstone Unified School District #1\Python NetMon\NetMon1.1.3.1\modules\application.py", line 59, in update_callback
    self.update_device_status(ip, message)
  File "c:\Users\ccollins\OneDrive - Tombstone Unified School District #1\Python NetMon\NetMon1.1.3.1\modules\application.py", line 137, in update_device_status
    self.master.after(0, update)
  File "C:\Program Files\WindowsApps\PythonSoftwareFoundation.Python.3.12_3.12.1008.0_x64__qbz5n2kfra8p0\Lib\tkinter\__init__.py", line 872, in after
    name = self._register(callit)
           ^^^^^^^^^^^^^^^^^^^^^^
  File "C:\Program Files\WindowsApps\PythonSoftwareFoundation.Python.3.12_3.12.1008.0_x64__qbz5n2kfra8p0\Lib\tkinter\__init__.py", line 1603, in _register
    self.tk.createcommand(name, f)
RuntimeError: main thread is not in main loop

During handling of the above exception, another exception occurred:

Traceback (most recent call last):
  File "C:\Program Files\WindowsApps\PythonSoftwareFoundation.Python.3.12_3.12.1008.0_x64__qbz5n2kfra8p0\Lib\concurrent\futures\_base.py", line 340, in _invoke_callbacks
    callback(self)
  File "c:\Users\ccollins\OneDrive - Tombstone Unified School District #1\Python NetMon\NetMon1.1.3.1\modules\network_operations.py", line 25, in <lambda>
    future.add_done_callback(lambda x: self.process_ping_result(x, ip))
                                       ^^^^^^^^^^^^^^^^^^^^^^^^^^^^^^^
  File "c:\Users\ccollins\OneDrive - Tombstone Unified School District #1\Python NetMon\NetMon1.1.3.1\modules\network_operations.py", line 63, in process_ping_result
    self.update_callback(ip, "Error: Failed to process ping result")
  File "c:\Users\ccollins\OneDrive - Tombstone Unified School District #1\Python NetMon\NetMon1.1.3.1\modules\application.py", line 62, in update_callback
    raise e
  File "c:\Users\ccollins\OneDrive - Tombstone Unified School District #1\Python NetMon\NetMon1.1.3.1\modules\application.py", line 59, in update_callback
    self.update_device_status(ip, message)
  File "c:\Users\ccollins\OneDrive - Tombstone Unified School District #1\Python NetMon\NetMon1.1.3.1\modules\application.py", line 137, in update_device_status
    self.master.after(0, update)
  File "C:\Program Files\WindowsApps\PythonSoftwareFoundation.Python.3.12_3.12.1008.0_x64__qbz5n2kfra8p0\Lib\tkinter\__init__.py", line 872, in after
    name = self._register(callit)
           ^^^^^^^^^^^^^^^^^^^^^^
  File "C:\Program Files\WindowsApps\PythonSoftwareFoundation.Python.3.12_3.12.1008.0_x64__qbz5n2kfra8p0\Lib\tkinter\__init__.py", line 1603, in _register
    self.tk.createcommand(name, f)
RuntimeError: main thread is not in main loop
2024-05-21 14:41:27,447 - ERROR - exception calling callback for <Future at 0x16f8ae98860 state=finished returned str>
Traceback (most recent call last):
  File "c:\Users\ccollins\OneDrive - Tombstone Unified School District #1\Python NetMon\NetMon1.1.3.1\modules\network_operations.py", line 59, in process_ping_result
    self.update_callback(ip, status)
  File "c:\Users\ccollins\OneDrive - Tombstone Unified School District #1\Python NetMon\NetMon1.1.3.1\modules\application.py", line 62, in update_callback
    raise e
  File "c:\Users\ccollins\OneDrive - Tombstone Unified School District #1\Python NetMon\NetMon1.1.3.1\modules\application.py", line 59, in update_callback
    self.update_device_status(ip, message)
  File "c:\Users\ccollins\OneDrive - Tombstone Unified School District #1\Python NetMon\NetMon1.1.3.1\modules\application.py", line 137, in update_device_status
    self.master.after(0, update)
  File "C:\Program Files\WindowsApps\PythonSoftwareFoundation.Python.3.12_3.12.1008.0_x64__qbz5n2kfra8p0\Lib\tkinter\__init__.py", line 872, in after
    name = self._register(callit)
           ^^^^^^^^^^^^^^^^^^^^^^
  File "C:\Program Files\WindowsApps\PythonSoftwareFoundation.Python.3.12_3.12.1008.0_x64__qbz5n2kfra8p0\Lib\tkinter\__init__.py", line 1603, in _register
    self.tk.createcommand(name, f)
RuntimeError: main thread is not in main loop

During handling of the above exception, another exception occurred:

Traceback (most recent call last):
  File "C:\Program Files\WindowsApps\PythonSoftwareFoundation.Python.3.12_3.12.1008.0_x64__qbz5n2kfra8p0\Lib\concurrent\futures\_base.py", line 340, in _invoke_callbacks
    callback(self)
  File "c:\Users\ccollins\OneDrive - Tombstone Unified School District #1\Python NetMon\NetMon1.1.3.1\modules\network_operations.py", line 25, in <lambda>
    future.add_done_callback(lambda x: self.process_ping_result(x, ip))
                                       ^^^^^^^^^^^^^^^^^^^^^^^^^^^^^^^
  File "c:\Users\ccollins\OneDrive - Tombstone Unified School District #1\Python NetMon\NetMon1.1.3.1\modules\network_operations.py", line 63, in process_ping_result
    self.update_callback(ip, "Error: Failed to process ping result")
  File "c:\Users\ccollins\OneDrive - Tombstone Unified School District #1\Python NetMon\NetMon1.1.3.1\modules\application.py", line 62, in update_callback
    raise e
  File "c:\Users\ccollins\OneDrive - Tombstone Unified School District #1\Python NetMon\NetMon1.1.3.1\modules\application.py", line 59, in update_callback
    self.update_device_status(ip, message)
  File "c:\Users\ccollins\OneDrive - Tombstone Unified School District #1\Python NetMon\NetMon1.1.3.1\modules\application.py", line 137, in update_device_status
    self.master.after(0, update)
  File "C:\Program Files\WindowsApps\PythonSoftwareFoundation.Python.3.12_3.12.1008.0_x64__qbz5n2kfra8p0\Lib\tkinter\__init__.py", line 872, in after
    name = self._register(callit)
           ^^^^^^^^^^^^^^^^^^^^^^
  File "C:\Program Files\WindowsApps\PythonSoftwareFoundation.Python.3.12_3.12.1008.0_x64__qbz5n2kfra8p0\Lib\tkinter\__init__.py", line 1603, in _register
    self.tk.createcommand(name, f)
RuntimeError: main thread is not in main loop
2024-05-22 06:18:30,919 - DEBUG - Logger set for ConfigManager
2024-05-22 06:18:30,919 - INFO - Application started
2024-05-22 06:18:31,595 - DEBUG - NetworkOperations initialized with ThreadPoolExecutor.
2024-05-22 06:18:31,597 - INFO - Pinging device with IP: 8.8.8.8
2024-05-22 06:18:31,597 - INFO - Pinging device with IP: 2.2.2.2
2024-05-22 06:18:31,597 - INFO - Pinging device with IP: 2.2.2.3
2024-05-22 06:18:35,842 - INFO - Result for device with IP 8.8.8.8: Online, Avg ping: 35.80 ms
2024-05-22 06:18:41,765 - INFO - Result for device with IP 2.2.2.2: Offline, Ping Timeout
2024-05-22 06:18:41,786 - INFO - Result for device with IP 2.2.2.3: Offline, Ping Timeout
2024-05-22 06:18:50,531 - INFO - Log display auto-refreshed.
2024-05-22 06:18:54,917 - INFO - Attempting to archive logs...
